Workbook
Name Balance: Setup!$C$11

Sheet Setup
B1: Annual budget tracker
B3: Plan and track your business income and expenses for the entire year.
B4: How to use this template
A5: 1. | B5: Get started by entering your starting balance below.
A6: 2. | B6: Then, fill out the 'Expenses' and 'Income' tabs.
A7: 3. | B7: Feel free to rename or delete categories in these tabs. Your changes will automatically be reflected on the 'Summary' tab, which shows an overview of your projected/actual spending.
B10: Configure
B11: Starting balance: | C11: 14000

Sheet Income
E1: Income | F1: 42370 | G1: 42401 | H1: 42430 | I1: 42461 | J1: 42491 | K1: 42522 | L1: 42552 | M1: 42583 | N1: 42614 | O1: 42644 | P1: 42675 | Q1: 42705 | R1: Total | S1: Average
B2: Sales | E2: Monthly totals: | F2: =sum(F3:F8) -> 0 | G2: =sum(G3:G8) -> 0 | H2: =sum(H3:H8) -> 0 | I2: =sum(I3:I8) -> 5000 | J2: =sum(J3:J8) -> 19400 | K2: =sum(K3:K8) -> 22400 | L2: =sum(L3:L8) -> 28320 | M2: =sum(M3:M8) -> 24320 | ... Q2: =sum(Q3:Q8) -> 27440 | R2: =sum(F2:Q2) -> 209480 | S2: =iferror(average(F2:Q2),"") -> 17456.667
E3: TPO Royalties | J3: 5000 | K3: 5000 | L3: 5000 | M3: 5000 | N3: 5000 | O3: 5000 | P3: 5000 | Q3: 5000 | R3: =sum(F3:Q3) -> 40000 | S3: =iferror(average(F3:Q3), "$0") -> 5000
E4: Ohio Royalties | R4: =sum(F4:Q4) -> 0 | S4: =iferror(average(F4:Q4), "$0") -> $0
E5: Hawaii Royalties | L5: 4000 | O5: 4000 | R5: =sum(F5:Q5) -> 8000 | S5: =iferror(average(F5:Q5), "$0") -> 4000
E6: CA - AA Gummies Distillate | I6: 5000 | J6: =(1500*2)*4.8 -> 14400 | K6: =(1500*2)*4.8 -> 14400 | L6: =(1700*2)*4.8 -> 16320 | M6: =(1700*2)*4.8 -> 16320 | N6: =(1700*2)*4.8 -> 16320 | O6: =(1900*2)*4.8 -> 18240 | P6: =(1900*2)*4.8 -> 18240 | Q6: =(1900*2)*4.8 -> 18240 | R6: =sum(F6:Q6) -> 137480 | S6: =iferror(average(F6:Q6), "$0") -> 15275.556
E7: CA - AA Gummies Rosin | K7: =500*6 -> 3000 | L7: =500*6 -> 3000 | M7: =500*6 -> 3000 | N7: =600*6 -> 3600 | O7: =600*6 -> 3600 | P7: =600*6 -> 3600 | Q7: =700*6 -> 4200 | R7: =sum(F7:Q7) -> 24000 | S7: =iferror(average(F7:Q7), "$0") -> 3428.5714
B10: Other | E10: Monthly totals: | F10: =sum(F11:F16) -> 0 | G10: =sum(G11:G16) -> 0 | H10: =sum(H11:H16) -> 0 | I10: =sum(I11:I16) -> 0 | J10: =sum(J11:J16) -> 0 | K10: =sum(K11:K16) -> 0 | L10: =sum(L11:L16) -> 0 | M10: =sum(M11:M16) -> 0 | ... Q10: =sum(Q11:Q16) -> 0 | R10: =sum(F10:Q10) -> 0 | S10: =iferror(average(F10:Q10),"") -> 0
E11: Cash Injection | R11: =sum(F11:Q11) -> 0 | S11: =iferror(average(F11:Q11), "$0") -> $0
E12: Other Portfolio Income | R12: =sum(F12:Q12) -> 0 | S12: =iferror(average(F12:Q12), "$0") -> $0
E13: Other Ordinary Income | R13: =sum(F13:Q13) -> 0 | S13: =iferror(average(F13:Q13), "$0") -> $0
E14: Refunds | R14: =sum(F14:Q14) -> 0 | S14: =iferror(average(F14:Q14), "$0") -> $0
E15: Other | R15: =sum(F15:Q15) -> 0 | S15: =iferror(average(F15:Q15), "$0") -> $0

Sheet Expenses
E1: Expenses | F1: 42370 | G1: 42401 | H1: 42430 | I1: 42461 | J1: 42491 | K1: 42522 | L1: 42552 | M1: 42583 | N1: 42614 | O1: 42644 | P1: 42675 | Q1: 42705 | R1: Total | S1: Average
B2: Manufacturing Cost | E2: Monthly totals: | F2: =sum(F3:F6) -> 0 | G2: =sum(G3:G6) -> 0 | H2: =sum(H3:H6) -> 0 | I2: =sum(I3:I6) -> 29600 | J2: =sum(J3:J6) -> 7500 | K2: =sum(K3:K6) -> 32400 | L2: =sum(L3:L6) -> 0 | M2: =sum(M3:M6) -> 13250 | ... Q2: =sum(Q3:Q6) -> 40800 | R2: 0 | S2: =iferror(average(F2:Q2),"") -> 13345.833
E3: Smoakland | I3: =(9500*2.8)+500*6 -> 29600 | K3: =(10500*2.8)+500*6 -> 32400 | N3: =(12000*2.8)+500*6 -> 36600 | Q3: =(13500*2.8)+500*6 -> 40800 | R3: =sum(F3:Q3) -> 139400 | S3: =iferror(average(F3:Q3), "$0") -> 34850
E4: MyGreen Network | J4: =(2000*3.5)+500*1 -> 7500 | M4: =(3500*3.5)+500*2 -> 13250 | R4: =sum(F4:Q4) -> 20750 | S4: =iferror(average(F4:Q4), "$0") -> 10375
E5: Raw Material | R5: =sum(F5:Q5) -> 0 | S5: =iferror(average(F5:Q5), "$0") -> $0
B8: Sales & Distribution Cost | E8: Monthly totals: | F8: =sum(F9:F14) -> 0 | G8: =sum(G9:G14) -> 0 | H8: =sum(H9:H14) -> 0 | I8: =sum(I9:I14) -> 2000 | J8: =sum(J9:J14) -> 5760 | K8: =sum(K9:K14) -> 6960 | L8: =sum(L9:L14) -> 7728 | M8: =sum(M9:M14) -> 7728 | ... Q8: =sum(Q9:Q14) -> 8976 | R8: =sum(F8:Q8) -> 64592 | S8: =iferror(average(F8:Q8),"") -> 5382.6667
E9: Luis Commissions & Fees | I9: =sum(Income!I6:I7)*12% -> 600 | J9: =sum(Income!J6:J7)*12% -> 1728 | K9: =sum(Income!K6:K7)*12% -> 2088 | L9: =sum(Income!L6:L7)*12% -> 2318.4 | M9: =sum(Income!M6:M7)*12% -> 2318.4 | N9: =sum(Income!N6:N7)*12% -> 2390.4 | O9: =sum(Income!O6:O7)*12% -> 2620.8 | P9: =sum(Income!P6:P7)*12% -> 2620.8 | Q9: =sum(Income!Q6:Q7)*12% -> 2692.8 | R9: =sum(F9:Q9) -> 19377.6 | S9: =iferror(average(F9:Q9), "$0") -> 2153.0667
E10: Distro Nabis Expense | I10: =sum(Income!I6:I7)*28% -> 1400 | J10: =sum(Income!J6:J7)*28% -> 4032 | K10: =sum(Income!K6:K7)*28% -> 4872 | L10: =sum(Income!L6:L7)*28% -> 5409.6 | M10: =sum(Income!M6:M7)*28% -> 5409.6 | N10: =sum(Income!N6:N7)*28% -> 5577.6 | O10: =sum(Income!O6:O7)*28% -> 6115.2 | P10: =sum(Income!P6:P7)*28% -> 6115.2 | Q10: =sum(Income!Q6:Q7)*28% -> 6283.2 | R10: =sum(F10:Q10) -> 45214.4 | S10: =iferror(average(F10:Q10), "$0") -> 5023.8222
E11: Professional Service Fee | R11: =sum(F11:Q11) -> 0 | S11: =iferror(average(F11:Q11), "$0") -> $0
E12: Marketting Assets | R12: =sum(F12:Q12) -> 0 | S12: =iferror(average(F12:Q12), "$0") -> $0
E13: Miscellaneous | R13: =sum(F13:Q13) -> 0 | S13: =iferror(average(F13:Q13), "$0") -> $0
B16: Office/General Administrative | E16: Monthly totals: | F16: =sum(F17:F25) -> 0 | G16: =sum(G17:G25) -> 0 | H16: =sum(H17:H25) -> 0 | I16: =sum(I17:I25) -> 0 | J16: =sum(J17:J25) -> 0 | K16: =sum(K17:K25) -> 0 | L16: =sum(L17:L25) -> 0 | M16: =sum(M17:M25) -> 0 | ... Q16: =sum(Q17:Q25) -> 0 | R16: =sum(F16:Q16) -> 0 | S16: =iferror(average(F16:Q16),"") -> 0
E17: Office Expenses | R17: =sum(F17:Q17) -> 0 | S17: =iferror(average(F17:Q17), "$0") -> $0
E18: Rent or Lease | R18: =sum(F18:Q18) -> 0 | S18: =iferror(average(F18:Q18), "$0") -> $0
E19: Supplies | R19: =sum(F19:Q19) -> 0 | S19: =iferror(average(F19:Q19), "$0") -> $0
E20: Stationary & Printing | R20: =sum(F20:Q20) -> 0 | S20: =iferror(average(F20:Q20), "$0") -> $0
E21: Repair & Maintenance | R21: =sum(F21:Q21) -> 0 | S21: =iferror(average(F21:Q21), "$0") -> $0
E22: Other General & Admin Expenses | R22: =sum(F22:Q22) -> 0 | S22: =iferror(average(F22:Q22), "$0") -> $0
E23: Utilities | R23: =sum(F23:Q23) -> 0 | S23: =iferror(average(F23:Q23), "$0") -> $0
E24: Shipping, Freight & Delivery | R24: =sum(F24:Q24) -> 0 | S24: =iferror(average(F24:Q24), "$0") -> $0
B27: Cost of Goods/Cost of Services | E27: Monthly totals: | F27: =sum(F28:F34) -> 0 | G27: =sum(G28:G34) -> 0 | H27: =sum(H28:H34) -> 0 | I27: =sum(I28:I34) -> 0 | J27: =sum(J28:J34) -> 0 | K27: =sum(K28:K34) -> 0 | L27: =sum(L28:L34) -> 0 | M27: =sum(M28:M34) -> 0 | ... Q27: =sum(Q28:Q34) -> 0 | R27: =sum(R28:R33) -> 0 | S27: =iferror(average(F27:Q27),"") -> 0
E28: Cost of Labor | R28: =sum(F28:Q28) -> 0 | S28: =iferror(average(F28:Q28), "$0") -> $0
E29: Freight & Delivery - COS | R29: =sum(F29:Q29) -> 0 | S29: =iferror(average(F29:Q29), "$0") -> $0
E30: Supplies & Materials - COGS | R30: =sum(F30:Q30) -> 0 | S30: =iferror(average(F30:Q30), "$0") -> $0
E31: Other Costs - COS | R31: =sum(F31:Q31) -> 0 | S31: =iferror(average(F31:Q31), "$0") -> $0
E32: Purchases - COS | R32: =sum(F32:Q32) -> 0 | S32: =iferror(average(F32:Q32), "$0") -> $0
E33: Job Materials | R33: =sum(F33:Q33) -> 0 | S33: =iferror(average(F33:Q33), "$0") -> $0
B36: Travel | E36: Monthly totals: | F36: =sum(F37:F43) -> 0 | G36: =sum(G37:G43) -> 0 | H36: =sum(H37:H43) -> 0 | I36: =sum(I37:I43) -> 0 | J36: =sum(J37:J43) -> 0 | K36: =sum(K37:K43) -> 0 | L36: =sum(L37:L43) -> 0 | M36: =sum(M37:M43) -> 0 | ... Q36: =sum(Q37:Q43) -> 0 | R36: =sum(F36:Q36) -> 0 | S36: =iferror(average(F36:Q36),"") -> 0
E37: Airfare | R37: =sum(F37:Q37) -> 0 | S37: =iferror(average(F37:Q37), "$0") -> $0
E38: Hotels | R38: =sum(F38:Q38) -> 0 | S38: =iferror(average(F38:Q38), "$0") -> $0
E39: Travel Meals | R39: =sum(F39:Q39) -> 0 | S39: =iferror(average(F39:Q39), "$0") -> $0
E40: Transportation | R40: =sum(F40:Q40) -> 0 | S40: =iferror(average(F40:Q40), "$0") -> $0
E41: Entertainment | R41: =sum(F41:Q41) -> 0 | S41: =iferror(average(F41:Q41), "$0") -> $0
E42: Other | R42: =sum(F42:Q42) -> 0 | S42: =iferror(average(F42:Q42), "$0") -> $0
B45: Legal | E45: Monthly totals: | F45: =sum(F46:F47) -> 0 | G45: =sum(G46:G47) -> 0 | H45: =sum(H46:H47) -> 0 | I45: =sum(I46:I47) -> 0 | J45: =sum(J46:J47) -> 0 | K45: =sum(K46:K47) -> 0 | L45: =sum(L46:L47) -> 0 | M45: =sum(M46:M47) -> 0 | ... Q45: =sum(Q46:Q47) -> 0 | R45: =sum(R46) -> 0 | S45: =iferror(average(F45:Q45),"") -> 0
E46: Legal & Professional Fees | R46: =sum(F46:Q46) -> 0 | S46: =iferror(average(F46:Q46), "$0") -> $0
B49: Insurance | E49: Monthly totals: | F49: =sum(F50:F54) -> 0 | G49: =sum(G50:G54) -> 0 | H49: =sum(H50:H54) -> 0 | I49: =sum(I50:I54) -> 0 | J49: =sum(J50:J54) -> 0 | K49: =sum(K50:K54) -> 0 | L49: =sum(L50:L54) -> 0 | M49: =sum(M50:M54) -> 0 | ... Q49: =sum(Q50:Q54) -> 0 | R49: =sum(F49:Q49) -> 0 | S49: =iferror(average(F49:Q49),"") -> 0
E50: Insurance - Disability | R50: =sum(F50:Q50) -> 0 | S50: =iferror(average(F50:Q50), "$0") -> $0
E51: Insurance - Liability | R51: =sum(F51:Q51) -> 0 | S51: =iferror(average(F51:Q51), "$0") -> $0
E52: Insurance - Errors & Omissions | R52: =sum(F52:Q52) -> 0 | S52: =iferror(average(F52:Q52), "$0") -> $0
...

Sheet Summary
D16: Summary
E17: Jan | F17: Feb | G17: Mar | H17: Apr | I17: May | J17: Jun | K17: Jul | L17: Aug | M17: Sep | N17: Oct | O17: Nov | P17: Dec | Q17: Total | R17: Average
D18: Income | E18: =sum(E25:E26) -> 0 | F18: =sum(F25:F27) -> 0 | G18: =sum(G25:G27) -> 0 | H18: =sum(H25:H27) -> 5000 | I18: =sum(I25:I27) -> 19400 | J18: =sum(J25:J27) -> 22400 | K18: =sum(K25:K27) -> 28320 | L18: =sum(L25:L27) -> 24320 | M18: =sum(M25:M27) -> 24920 | ... P18: =sum(P25:P27) -> 27440 | Q18: =sum(E18:P18) -> 209480 | R18: =iferror(averageif(E18:P18, ">0", E18:P18),"") -> 23275.556
D19: Expenses | E19: =sum(E30:E39) -> 0 | F19: =sum(F30:F39) -> 0 | G19: =sum(G30:G39) -> 0 | H19: =sum(H30:H39) -> 31600 | I19: =sum(I30:I39) -> 13260 | J19: =sum(J30:J39) -> 39360 | K19: =sum(K30:K39) -> 7728 | L19: =sum(L30:L39) -> 20978 | ... P19: =sum(P30:P39) -> 49776 | Q19: =sum(E19:P19) -> 224742 | R19: =iferror(averageif(E19:P19, ">0", E19:P19),"") -> 24971.333
D20: Net savings | E20: =E18-E19 -> 0 | F20: =F18-F19 -> 0 | G20: =G18-G19 -> 0 | H20: =H18-H19 -> -26600 | I20: =I18-I19 -> 6140 | J20: =J18-J19 -> -16960 | K20: =K18-K19 -> 20592 | L20: =L18-L19 -> 3342 | ... P20: =P18-P19 -> -22336 | Q20: =sum(E20:P20) -> -15262 | R20: =iferror(averageif(E20:P20, ">0", E20:P20),"") -> 14056.4
D21: Ending balance | E21: =(Balance+E18)-E19 -> 14000 | F21: =(E21+F18)-F19 -> 14000 | G21: =(F21+G18)-G19 -> 14000 | H21: =(G21+H18)-H19 -> -12600 | I21: =(H21+I18)-I19 -> -6460 | J21: =(I21+J18)-J19 -> -23420 | K21: =(J21+K18)-K19 -> -2828 | L21: =(K21+L18)-L19 -> 514 | M21: =(L21+M18)-M19 -> -19134 | ... P21: =(O21+P18)-P19 -> -1262 | R21: =iferror(averageif(E21:P21, ">0", E21:P21),"") -> 11093
D23: Income
B24: Row # | D24: {=unique(Income!B:B)} | E24: Jan | F24: Feb | G24: Mar | H24: Apr | I24: May | J24: Jun | K24: Jul | L24: Aug | M24: Sep | N24: Oct | O24: Nov | P24: Dec | Q24: Total | R24: Average
B25: {=iferror(match(D25:D26,Income!B:B,0),"")} -> 2 | D25: Sales | E25: =if(not(isblank(B25)), indirect("Income!F"&B25&":S"&B25),"") -> 0 | F25: 0 | G25: 0 | H25: 5000 | I25: 19400 | J25: 22400 | K25: 28320 | L25: 24320 | M25: 24920 | N25: 30840 | O25: 26840 | P25: 27440 | Q25: 209480 | R25: 17456.667
B26: 10 | D26: Other | E26: =if(not(isblank(B26)), indirect("Income!F"&B26&":S"&B26),"") -> 0 | F26: 0 | G26: 0 | H26: 0 | I26: 0 | J26: 0 | K26: 0 | L26: 0 | M26: 0 | N26: 0 | O26: 0 | P26: 0 | Q26: 0 | R26: 0
D28: Expenses
B29: Row # | D29: {=unique(Expenses!B:B)} | E29: Jan | F29: Feb | G29: Mar | H29: Apr | I29: May | J29: Jun | K29: Jul | L29: Aug | M29: Sep | N29: Oct | O29: Nov | P29: Dec | Q29: Total | R29: Average
B30: {=iferror(match(D30:D38,Expenses!B:B,0),"")} -> 2 | D30: Manufacturing Cost | E30: =if(not(isblank(B30)), indirect("Expenses!F"&B30&":S"&B30),"") -> 0 | F30: 0 | G30: 0 | H30: 29600 | I30: 7500 | J30: 32400 | K30: 0 | L30: 13250 | M30: 36600 | N30: 0 | O30: 0 | P30: 40800 | Q30: 0 | R30: 13345.833
B31: 8 | D31: Sales & Distribution Cost | E31: =if(not(isblank(B31)), indirect("Expenses!F"&B31&":S"&B31),"") -> 0 | F31: 0 | G31: 0 | H31: 2000 | I31: 5760 | J31: 6960 | K31: 7728 | L31: 7728 | M31: 7968 | N31: 8736 | O31: 8736 | P31: 8976 | Q31: 64592 | R31: 5382.6667
B32: 16 | D32: Office/General Administrative | E32: =if(not(isblank(B32)), indirect("Expenses!F"&B32&":S"&B32),"") -> 0 | F32: 0 | G32: 0 | H32: 0 | I32: 0 | J32: 0 | K32: 0 | L32: 0 | M32: 0 | N32: 0 | O32: 0 | P32: 0 | Q32: 0 | R32: 0
B33: 27 | D33: Cost of Goods/Cost of Services | E33: =if(not(isblank(B33)), indirect("Expenses!F"&B33&":S"&B33),"") -> 0 | F33: 0 | G33: 0 | H33: 0 | I33: 0 | J33: 0 | K33: 0 | L33: 0 | M33: 0 | N33: 0 | O33: 0 | P33: 0 | Q33: 0 | R33: 0
B34: 36 | D34: Travel | E34: =if(not(isblank(B34)), indirect("Expenses!F"&B34&":S"&B34),"") -> 0 | F34: 0 | G34: 0 | H34: 0 | I34: 0 | J34: 0 | K34: 0 | L34: 0 | M34: 0 | N34: 0 | O34: 0 | P34: 0 | Q34: 0 | R34: 0
B35: 45 | D35: Legal | E35: =if(not(isblank(B35)), indirect("Expenses!F"&B35&":S"&B35),"") -> 0 | F35: 0 | G35: 0 | H35: 0 | I35: 0 | J35: 0 | K35: 0 | L35: 0 | M35: 0 | N35: 0 | O35: 0 | P35: 0 | Q35: 0 | R35: 0
B36: 49 | D36: Insurance | E36: =if(not(isblank(B36)), indirect("Expenses!F"&B36&":S"&B36),"") -> 0 | F36: 0 | G36: 0 | H36: 0 | I36: 0 | J36: 0 | K36: 0 | L36: 0 | M36: 0 | N36: 0 | O36: 0 | P36: 0 | Q36: 0 | R36: 0
B37: 56 | D37: Other Expenses | E37: =if(not(isblank(B37)), indirect("Expenses!F"&B37&":S"&B37),"") -> 0 | F37: 0 | G37: 0 | H37: 0 | I37: 0 | J37: 0 | K37: 0 | L37: 0 | M37: 0 | N37: 0 | O37: 0 | P37: 0 | Q37: 0 | R37: 0
B38: 63 | D38: Taxes | E38: =if(not(isblank(B38)), indirect("Expenses!F"&B38&":S"&B38),"") -> 0 | F38: 0 | G38: 0 | H38: 0 | I38: 0 | J38: 0 | K38: 0 | L38: 0 | M38: 0 | N38: 0 | O38: 0 | P38: 0 | Q38: 0 | R38: 0
E39: =if(not(isblank(B39)), indirect("Expenses!D"&B39&":Q"&B39),"")
E40: =if(not(isblank(B40)), indirect("Expenses!D"&B40&":Q"&B40),"")
E41: =if(not(isblank(B41)), indirect("Expenses!D"&B41&":Q"&B41),"")
E42: =if(not(isblank(B42)), indirect("Expenses!D"&B42&":Q"&B42),"")
E43: =if(not(isblank(B43)), indirect("Expenses!D"&B43&":Q"&B43),"")
E44: =if(not(isblank(B44)), indirect("Expenses!D"&B44&":Q"&B44),"")
E45: =if(not(isblank(B45)), indirect("Expenses!D"&B45&":Q"&B45),"")
E46: =if(not(isblank(B46)), indirect("Expenses!D"&B46&":Q"&B46),"")
E47: =if(not(isblank(B47)), indirect("Expenses!D"&B47&":Q"&B47),"")
E48: =if(not(isblank(B48)), indirect("Expenses!D"&B48&":Q"&B48),"")
E49: =if(not(isblank(B49)), indirect("Expenses!D"&B49&":Q"&B49),"")
E50: =if(not(isblank(B50)), indirect("Expenses!D"&B50&":Q"&B50),"")
... E57: =if(not(isblank(B57)), indirect("Expenses!D"&B57&":Q"&B57),"")
